Workbook

Sheet student_habits_performance
A1: student_id | B1: age | C1: gender | D1: study_hours_per_day | E1: social_media_hours | F1: netflix_hours | G1: part_time_job | H1: attendance_percentage | I1: sleep_hours | J1: diet_quality | K1: exercise_frequency | L1: parental_education_level | M1: internet_quality | N1: mental_health_rating | O1: extracurricular_participation | P1: exam_score
A2: S1000 | B2: 23 | C2: Female | D2: 0 | E2: 1.2 | F2: 1.1 | G2: No | H2: 85 | I2: 8 | J2: Fair | K2: 6 | L2: Master | M2: Average | N2: 8 | O2: Yes | P2: 56.2 | Q2: =ROUND(P2/25,0) -> 2
A3: S1001 | B3: 20 | C3: Female | D3: 6.9 | E3: 2.8 | F3: 2.3 | G3: No | H3: 97.3 | I3: 4.6 | J3: Good | K3: 6 | L3: High School | M3: Average | N3: 8 | O3: No | P3: 100 | Q3: =ROUND(P3/25,0) -> 4
A4: S1002 | B4: 21 | C4: Male | D4: 1.4 | E4: 3.1 | F4: 1.3 | G4: No | H4: 94.8 | I4: 8 | J4: Poor | K4: 1 | L4: High School | M4: Poor | N4: 1 | O4: No | P4: 34.3 | Q4: =ROUND(P4/25,0) -> 1
A5: S1003 | B5: 23 | C5: Female | D5: 1 | E5: 3.9 | F5: 1 | G5: No | H5: 71 | I5: 9.2 | J5: Poor | K5: 4 | L5: Master | M5: Good | N5: 1 | O5: Yes | P5: 26.8 | Q5: =ROUND(P5/25,0) -> 1
A6: S1004 | B6: 19 | C6: Female | D6: 5 | E6: 4.4 | F6: 0.5 | G6: No | H6: 90.9 | I6: 4.9 | J6: Fair | K6: 3 | L6: Master | M6: Good | N6: 1 | O6: No | P6: 66.4 | Q6: =ROUND(P6/25,0) -> 3
A7: S1005 | B7: 24 | C7: Male | D7: 7.2 | E7: 1.3 | F7: 0 | G7: No | H7: 82.9 | I7: 7.4 | J7: Fair | K7: 1 | L7: Master | M7: Average | N7: 4 | O7: No | P7: 100 | Q7: =ROUND(P7/25,0) -> 4
A8: S1006 | B8: 21 | C8: Female | D8: 5.6 | E8: 1.5 | F8: 1.4 | G8: Yes | H8: 85.8 | I8: 6.5 | J8: Good | K8: 2 | L8: Master | M8: Poor | N8: 4 | O8: No | P8: 89.8 | Q8: =ROUND(P8/25,0) -> 4
A9: S1007 | B9: 21 | C9: Female | D9: 4.3 | E9: 1 | F9: 2 | G9: Yes | H9: 77.7 | I9: 4.6 | J9: Fair | K9: 0 | L9: Bachelor | M9: Average | N9: 8 | O9: No | P9: 72.6 | Q9: =ROUND(P9/25,0) -> 3
A10: S1008 | B10: 23 | C10: Female | D10: 4.4 | E10: 2.2 | F10: 1.7 | G10: No | H10: 100 | I10: 7.1 | J10: Good | K10: 3 | L10: Bachelor | M10: Good | N10: 1 | O10: No | P10: 78.9 | Q10: =ROUND(P10/25,0) -> 3
A11: S1009 | B11: 18 | C11: Female | D11: 4.8 | E11: 3.1 | F11: 1.3 | G11: No | H11: 95.4 | I11: 7.5 | J11: Good | K11: 5 | L11: Bachelor | M11: Good | N11: 10 | O11: Yes | P11: 100 | Q11: =ROUND(P11/25,0) -> 4
A12: S1010 | B12: 19 | C12: Female | D12: 4.6 | E12: 3.7 | F12: 0.8 | G12: No | H12: 77.6 | I12: 5.8 | J12: Fair | K12: 1 | L12: None | M12: Good | N12: 3 | O12: No | P12: 63.3 | Q12: =ROUND(P12/25,0) -> 3
A13: S1011 | B13: 23 | C13: Male | D13: 3.9 | E13: 2.4 | F13: 2.5 | G13: No | H13: 71.7 | I13: 7.9 | J13: Fair | K13: 2 | L13: Bachelor | M13: Average | N13: 1 | O13: No | P13: 74.4 | Q13: =ROUND(P13/25,0) -> 3
... A1001: S1999 | B1001: 19 | C1001: Female | D1001: 4.3 | E1001: 2.9 | F1001: 1.9 | G1001: No | H1001: 89.4 | I1001: 7.1 | J1001: Good | K1001: 2 | L1001: Bachelor | M1001: Average | N1001: 8 | O1001: No | P1001: 74.9 | Q1001: =ROUND(P1001/25,0) -> 3

Sheet scaled (2)
A1: Student Name | B1: Gender | C1: Emis id | D1: Private_Tutoring | E1: Sleep_Hours | F1: Mobile_Usage_Hours | G1: Motivation_Level | H1: Stress_Level | I1: Study_Environment | J1: Parental_Education | K1: Family_Income_Level | L1: Peer_Influence | M1: Physical_Health_Rating | N1: Chronic_Illness | O1: Attendance_Percentage | P1: Risk_Level (TARGET)
A2: Asmita Thapa | B2: Female | C2: 2703100947805132 | D2: =student_habits_performance!O2 -> Yes | E2: =student_habits_performance!I2 -> 8 | F2: =student_habits_performance!E2 -> 1.2 | G2: 1 | H2: =ROUND(LOG(student_habits_performance!N2),0) -> 1 | I2: =student_habits_performance!J2 -> Fair | J2: =student_habits_performance!L2 -> Master | K2: =student_habits_performance!M2 -> Average | L2: =ROUND(student_habits_performance!F2,0) -> 1 | M2: =student_habits_performance!K2 -> 6 | N2: =student_habits_performance!G2 -> No | O2: =student_habits_performance!H2 -> 85 | P2: =student_habits_performance!Q2 -> 2
A3: Kamal K C | B3: Male | C3: 2703100947906290 | D3: =student_habits_performance!O3 -> No | E3: =student_habits_performance!I3 -> 4.6 | F3: =student_habits_performance!E3 -> 2.8 | G3: 2 | H3: =ROUND(LOG(student_habits_performance!N3),0) -> 1 | I3: =student_habits_performance!J3 -> Good | J3: =student_habits_performance!L3 -> High School | K3: =student_habits_performance!M3 -> Average | L3: =ROUND(student_habits_performance!F3,0) -> 2 | M3: =student_habits_performance!K3 -> 6 | N3: =student_habits_performance!G3 -> No | O3: =student_habits_performance!H3 -> 97.3 | P3: =student_habits_performance!Q3 -> 4
A4: Asmita Yesmali Magar | B4: Female | C4: 2703100947502860 | D4: =student_habits_performance!O4 -> No | E4: =student_habits_performance!I4 -> 8 | F4: =student_habits_performance!E4 -> 3.1 | G4: 3 | H4: =ROUND(LOG(student_habits_performance!N4),0) -> 0 | I4: =student_habits_performance!J4 -> Poor | J4: =student_habits_performance!L4 -> High School | K4: =student_habits_performance!M4 -> Poor | L4: =ROUND(student_habits_performance!F4,0) -> 1 | M4: =student_habits_performance!K4 -> 1 | N4: =student_habits_performance!G4 -> No | O4: =student_habits_performance!H4 -> 94.8 | P4: =student_habits_performance!Q4 -> 1
A5: Tushi Kr. Chaurasiya | B5: Male | C5: 2703100947906670 | D5: =student_habits_performance!O5 -> Yes | E5: =student_habits_performance!I5 -> 9.2 | F5: =student_habits_performance!E5 -> 3.9 | G5: 2 | H5: =ROUND(LOG(student_habits_performance!N5),0) -> 0 | I5: =student_habits_performance!J5 -> Poor | J5: =student_habits_performance!L5 -> Master | K5: =student_habits_performance!M5 -> Good | L5: =ROUND(student_habits_performance!F5,0) -> 1 | M5: =student_habits_performance!K5 -> 4 | N5: =student_habits_performance!G5 -> No | O5: =student_habits_performance!H5 -> 71 | P5: =student_habits_performance!Q5 -> 1
A6: Tulasi Kumari Khadga | B6: Female | C6: 2703100947805129 | D6: =student_habits_performance!O6 -> No | E6: =student_habits_performance!I6 -> 4.9 | F6: =student_habits_performance!E6 -> 4.4 | G6: 4 | H6: =ROUND(LOG(student_habits_performance!N6),0) -> 0 | I6: =student_habits_performance!J6 -> Fair | J6: =student_habits_performance!L6 -> Master | K6: =student_habits_performance!M6 -> Good | L6: =ROUND(student_habits_performance!F6,0) -> 1 | M6: =student_habits_performance!K6 -> 3 | N6: =student_habits_performance!G6 -> No | O6: =student_habits_performance!H6 -> 90.9 | P6: =student_habits_performance!Q6 -> 3
A7: Sushil Chandra Subedi | B7: Male | C7: 2703100947906057 | D7: =student_habits_performance!O7 -> No | E7: =student_habits_performance!I7 -> 7.4 | F7: =student_habits_performance!E7 -> 1.3 | G7: 0 | H7: =ROUND(LOG(student_habits_performance!N7),0) -> 1 | I7: =student_habits_performance!J7 -> Fair | J7: =student_habits_performance!L7 -> Master | K7: =student_habits_performance!M7 -> Average | L7: =ROUND(student_habits_performance!F7,0) -> 0 | M7: =student_habits_performance!K7 -> 1 | N7: =student_habits_performance!G7 -> No | O7: =student_habits_performance!H7 -> 82.9 | P7: =student_habits_performance!Q7 -> 4
A8: Suraj Kumar Yadav | B8: Male | C8: 2703100947805100 | D8: =student_habits_performance!O8 -> No | E8: =student_habits_performance!I8 -> 6.5 | F8: =student_habits_performance!E8 -> 1.5 | G8: 3 | H8: =ROUND(LOG(student_habits_performance!N8),0) -> 1 | I8: =student_habits_performance!J8 -> Good | J8: =student_habits_performance!L8 -> Master | K8: =student_habits_performance!M8 -> Poor | L8: =ROUND(student_habits_performance!F8,0) -> 1 | M8: =student_habits_performance!K8 -> 2 | N8: =student_habits_performance!G8 -> Yes | O8: =student_habits_performance!H8 -> 85.8 | P8: =student_habits_performance!Q8 -> 4
A9: Sima Bisunkhe | B9: Female | C9: 2703100947502857 | D9: =student_habits_performance!O9 -> No | E9: =student_habits_performance!I9 -> 4.6 | F9: =student_habits_performance!E9 -> 1 | G9: 4 | H9: =ROUND(LOG(student_habits_performance!N9),0) -> 1 | I9: =student_habits_performance!J9 -> Fair | J9: =student_habits_performance!L9 -> Bachelor | K9: =student_habits_performance!M9 -> Average | L9: =ROUND(student_habits_performance!F9,0) -> 2 | M9: =student_habits_performance!K9 -> 0 | N9: =student_habits_performance!G9 -> Yes | O9: =student_habits_performance!H9 -> 77.7 | P9: =student_habits_performance!Q9 -> 3
A10: Sudip Baniya | B10: Male | C10: 2703100948007108 | D10: =student_habits_performance!O10 -> No | E10: =student_habits_performance!I10 -> 7.1 | F10: =student_habits_performance!E10 -> 2.2 | G10: 2 | H10: =ROUND(LOG(student_habits_performance!N10),0) -> 0 | I10: =student_habits_performance!J10 -> Good | J10: =student_habits_performance!L10 -> Bachelor | K10: =student_habits_performance!M10 -> Good | L10: =ROUND(student_habits_performance!F10,0) -> 2 | M10: =student_habits_performance!K10 -> 3 | N10: =student_habits_performance!G10 -> No | O10: =student_habits_performance!H10 -> 100 | P10: =student_habits_performance!Q10 -> 3
A11: Sparsh Sah | B11: Male | C11: 2703100947906143 | D11: =student_habits_performance!O11 -> Yes | E11: =student_habits_performance!I11 -> 7.5 | F11: =student_habits_performance!E11 -> 3.1 | G11: 0 | H11: =ROUND(LOG(student_habits_performance!N11),0) -> 1 | I11: =student_habits_performance!J11 -> Good | J11: =student_habits_performance!L11 -> Bachelor | K11: =student_habits_performance!M11 -> Good | L11: =ROUND(student_habits_performance!F11,0) -> 1 | M11: =student_habits_performance!K11 -> 5 | N11: =student_habits_performance!G11 -> No | O11: =student_habits_performance!H11 -> 95.4 | P11: =student_habits_performance!Q11 -> 4
A12: Sitala Parajuli | B12: Female | C12: 2703100947502855 | D12: =student_habits_performance!O12 -> No | E12: =student_habits_performance!I12 -> 5.8 | F12: =student_habits_performance!E12 -> 3.7 | G12: 4 | H12: =ROUND(LOG(student_habits_performance!N12),0) -> 0 | I12: =student_habits_performance!J12 -> Fair | J12: =student_habits_performance!L12 -> None | K12: =student_habits_performance!M12 -> Good | L12: =ROUND(student_habits_performance!F12,0) -> 1 | M12: =student_habits_performance!K12 -> 1 | N12: =student_habits_performance!G12 -> No | O12: =student_habits_performance!H12 -> 77.6 | P12: =student_habits_performance!Q12 -> 3
A13: Siddhartha Khanal | B13: Male | C13: 2703100947906078 | D13: =student_habits_performance!O13 -> No | E13: =student_habits_performance!I13 -> 7.9 | F13: =student_habits_performance!E13 -> 2.4 | G13: 2 | H13: =ROUND(LOG(student_habits_performance!N13),0) -> 0 | I13: =student_habits_performance!J13 -> Fair | J13: =student_habits_performance!L13 -> Bachelor | K13: =student_habits_performance!M13 -> Average | L13: =ROUND(student_habits_performance!F13,0) -> 3 | M13: =student_habits_performance!K13 -> 2 | N13: =student_habits_performance!G13 -> No | O13: =student_habits_performance!H13 -> 71.7 | P13: =student_habits_performance!Q13 -> 3
... A1001: Tek Bahadur Bhujel | B1001: Male | C1001: 2703100948200289 | D1001: =student_habits_performance!O1001 -> No | E1001: =student_habits_performance!I1001 -> 7.1 | F1001: =student_habits_performance!E1001 -> 2.9 | G1001: 0 | H1001: =ROUND(LOG(student_habits_performance!N1001),0) -> 1 | I1001: =student_habits_performance!J1001 -> Good | J1001: =student_habits_performance!L1001 -> Bachelor | K1001: =student_habits_performance!M1001 -> Average | L1001: =ROUND(student_habits_performance!F1001,0) -> 2 | M1001: =student_habits_performance!K1001 -> 2 | N1001: =student_habits_performance!G1001 -> No | O1001: =student_habits_performance!H1001 -> 89.4 | P1001: =student_habits_performance!Q1001 -> 3

Sheet Sheet1
A1: Student Name | B1: Gender | C1: Emis id | D1: Private_Tutoring | E1: Sleep_Hours | F1: Mobile_Usage_Hours | G1: Motivation_Level | H1: Stress_Level | I1: Study_Environment | J1: Parental_Education | K1: Family_Income_Level | L1: Peer_Influence | M1: Physical_Health_Rating | N1: Chronic_Illness | O1: Attendance_Percentage | P1: Risk_Level (TARGET)
A2: Aashika Dhakal | B2: Female | C2: 2703100948006719 | D2: =student_habits_performance!O2 -> Yes | E2: =student_habits_performance!I2 -> 8 | F2: =student_habits_performance!E2 -> 1.2 | G2: =RANDBETWEEN(0,4) -> 3 | H2: =ROUND(LOG(student_habits_performance!N2),0) -> 1 | I2: =student_habits_performance!J2 -> Fair | J2: =student_habits_performance!L2 -> Master | K2: =student_habits_performance!M2 -> Average | L2: =ROUND(student_habits_performance!F2,0) -> 1 | M2: =student_habits_performance!K2 -> 6 | N2: =student_habits_performance!G2 -> No | O2: =student_habits_performance!H2 -> 85 | P2: =student_habits_performance!Q2 -> 2
A3: Rabi Krishna Baitha | B3: Male | C3: 2703100948006711 | D3: =student_habits_performance!O3 -> No | E3: =student_habits_performance!I3 -> 4.6 | F3: =student_habits_performance!E3 -> 2.8 | G3: =RANDBETWEEN(0,4) -> 3 | H3: =ROUND(LOG(student_habits_performance!N3),0) -> 1 | I3: =student_habits_performance!J3 -> Good | J3: =student_habits_performance!L3 -> High School | K3: =student_habits_performance!M3 -> Average | L3: =ROUND(student_habits_performance!F3,0) -> 2 | M3: =student_habits_performance!K3 -> 6 | N3: =student_habits_performance!G3 -> No | O3: =student_habits_performance!H3 -> 97.3 | P3: =student_habits_performance!Q3 -> 4
A4: Shivam Kumar Ram | B4: Male | C4: 2703100948006716 | D4: =student_habits_performance!O4 -> No | E4: =student_habits_performance!I4 -> 8 | F4: =student_habits_performance!E4 -> 3.1 | G4: =RANDBETWEEN(0,4) -> 4 | H4: =ROUND(LOG(student_habits_performance!N4),0) -> 0 | I4: =student_habits_performance!J4 -> Poor | J4: =student_habits_performance!L4 -> High School | K4: =student_habits_performance!M4 -> Poor | L4: =ROUND(student_habits_performance!F4,0) -> 1 | M4: =student_habits_performance!K4 -> 1 | N4: =student_habits_performance!G4 -> No | O4: =student_habits_performance!H4 -> 94.8 | P4: =student_habits_performance!Q4 -> 1
A5: Bhuwan Karki | B5: Male | C5: 2703100948006710 | D5: =student_habits_performance!O5 -> Yes | E5: =student_habits_performance!I5 -> 9.2 | F5: =student_habits_performance!E5 -> 3.9 | G5: =RANDBETWEEN(0,4) -> 1 | H5: =ROUND(LOG(student_habits_performance!N5),0) -> 0 | I5: =student_habits_performance!J5 -> Poor | J5: =student_habits_performance!L5 -> Master | K5: =student_habits_performance!M5 -> Good | L5: =ROUND(student_habits_performance!F5,0) -> 1 | M5: =student_habits_performance!K5 -> 4 | N5: =student_habits_performance!G5 -> No | O5: =student_habits_performance!H5 -> 71 | P5: =student_habits_performance!Q5 -> 1
A6: Khil Raj Sedhain | B6: Male | C6: 2703100948007300 | D6: =student_habits_performance!O6 -> No | E6: =student_habits_performance!I6 -> 4.9 | F6: =student_habits_performance!E6 -> 4.4 | G6: =RANDBETWEEN(0,4) -> 4 | H6: =ROUND(LOG(student_habits_performance!N6),0) -> 0 | I6: =student_habits_performance!J6 -> Fair | J6: =student_habits_performance!L6 -> Master | K6: =student_habits_performance!M6 -> Good | L6: =ROUND(student_habits_performance!F6,0) -> 1 | M6: =student_habits_performance!K6 -> 3 | N6: =student_habits_performance!G6 -> No | O6: =student_habits_performance!H6 -> 90.9 | P6: =student_habits_performance!Q6 -> 3
A7: Nisal Kumar Yadav | B7: Male | C7: 2703100948007299 | D7: =student_habits_performance!O7 -> No | E7: =student_habits_performance!I7 -> 7.4 | F7: =student_habits_performance!E7 -> 1.3 | G7: =RANDBETWEEN(0,4) -> 3 | H7: =ROUND(LOG(student_habits_performance!N7),0) -> 1 | I7: =student_habits_performance!J7 -> Fair | J7: =student_habits_performance!L7 -> Master | K7: =student_habits_performance!M7 -> Average | L7: =ROUND(student_habits_performance!F7,0) -> 0 | M7: =student_habits_performance!K7 -> 1 | N7: =student_habits_performance!G7 -> No | O7: =student_habits_performance!H7 -> 82.9 | P7: =student_habits_performance!Q7 -> 4
A8: Debit B.K. | B8: Male | C8: 2703100948100022 | D8: =student_habits_performance!O8 -> No | E8: =student_habits_performance!I8 -> 6.5 | F8: =student_habits_performance!E8 -> 1.5 | G8: =RANDBETWEEN(0,4) -> 3 | H8: =ROUND(LOG(student_habits_performance!N8),0) -> 1 | I8: =student_habits_performance!J8 -> Good | J8: =student_habits_performance!L8 -> Master | K8: =student_habits_performance!M8 -> Poor | L8: =ROUND(student_habits_performance!F8,0) -> 1 | M8: =student_habits_performance!K8 -> 2 | N8: =student_habits_performance!G8 -> Yes | O8: =student_habits_performance!H8 -> 85.8 | P8: =student_habits_performance!Q8 -> 4
A9: Binita Magar | B9: Female | C9: 2703100948006712 | D9: =student_habits_performance!O9 -> No | E9: =student_habits_performance!I9 -> 4.6 | F9: =student_habits_performance!E9 -> 1 | G9: =RANDBETWEEN(0,4) -> 1 | H9: =ROUND(LOG(student_habits_performance!N9),0) -> 1 | I9: =student_habits_performance!J9 -> Fair | J9: =student_habits_performance!L9 -> Bachelor | K9: =student_habits_performance!M9 -> Average | L9: =ROUND(student_habits_performance!F9,0) -> 2 | M9: =student_habits_performance!K9 -> 0 | N9: =student_habits_performance!G9 -> Yes | O9: =student_habits_performance!H9 -> 77.7 | P9: =student_habits_performance!Q9 -> 3
A10: Priyanka Kumari | B10: Female | C10: 2703100948006709 | D10: =student_habits_performance!O10 -> No | E10: =student_habits_performance!I10 -> 7.1 | F10: =student_habits_performance!E10 -> 2.2 | G10: =RANDBETWEEN(0,4) -> 1 | H10: =ROUND(LOG(student_habits_performance!N10),0) -> 0 | I10: =student_habits_performance!J10 -> Good | J10: =student_habits_performance!L10 -> Bachelor | K10: =student_habits_performance!M10 -> Good | L10: =ROUND(student_habits_performance!F10,0) -> 2 | M10: =student_habits_performance!K10 -> 3 | N10: =student_habits_performance!G10 -> No | O10: =student_habits_performance!H10 -> 100 | P10: =student_habits_performance!Q10 -> 3
A11: Krishtina Pokharel | B11: Female | C11: 2703100948006713 | D11: =student_habits_performance!O11 -> Yes | E11: =student_habits_performance!I11 -> 7.5 | F11: =student_habits_performance!E11 -> 3.1 | G11: =RANDBETWEEN(0,4) -> 2 | H11: =ROUND(LOG(student_habits_performance!N11),0) -> 1 | I11: =student_habits_performance!J11 -> Good | J11: =student_habits_performance!L11 -> Bachelor | K11: =student_habits_performance!M11 -> Good | L11: =ROUND(student_habits_performance!F11,0) -> 1 | M11: =student_habits_performance!K11 -> 5 | N11: =student_habits_performance!G11 -> No | O11: =student_habits_performance!H11 -> 95.4 | P11: =student_habits_performance!Q11 -> 4
A12: Raj Yadav | B12: Female | C12: 2703100947905693 | D12: =student_habits_performance!O12 -> No | E12: =student_habits_performance!I12 -> 5.8 | F12: =student_habits_performance!E12 -> 3.7 | G12: =RANDBETWEEN(0,4) -> 1 | H12: =ROUND(LOG(student_habits_performance!N12),0) -> 0 | I12: =student_habits_performance!J12 -> Fair | J12: =student_habits_performance!L12 -> None | K12: =student_habits_performance!M12 -> Good | L12: =ROUND(student_habits_performance!F12,0) -> 1 | M12: =student_habits_performance!K12 -> 1 | N12: =student_habits_performance!G12 -> No | O12: =student_habits_performance!H12 -> 77.6 | P12: =student_habits_performance!Q12 -> 3
A13: Anchit Kumar Baitha | B13: Male | C13: 2703100948006718 | D13: =student_habits_performance!O13 -> No | E13: =student_habits_performance!I13 -> 7.9 | F13: =student_habits_performance!E13 -> 2.4 | G13: =RANDBETWEEN(0,4) -> 3 | H13: =ROUND(LOG(student_habits_performance!N13),0) -> 0 | I13: =student_habits_performance!J13 -> Fair | J13: =student_habits_performance!L13 -> Bachelor | K13: =student_habits_performance!M13 -> Average | L13: =ROUND(student_habits_performance!F13,0) -> 3 | M13: =student_habits_performance!K13 -> 2 | N13: =student_habits_performance!G13 -> No | O13: =student_habits_performance!H13 -> 71.7 | P13: =student_habits_performance!Q13 -> 3
... A120: Sinjal Gupta | B120: Female | C120: 2703100948200095 | D120: =student_habits_performance!O120 -> Yes | E120: =student_habits_performance!I120 -> 6.9 | F120: =student_habits_performance!E120 -> 3.3 | G120: =RANDBETWEEN(0,4) -> 1 | H120: =ROUND(LOG(student_habits_performance!N120),0) -> 0 | I120: =student_habits_performance!J120 -> Poor | J120: =student_habits_performance!L120 -> Bachelor | K120: =student_habits_performance!M120 -> Good | L120: =ROUND(student_habits_performance!F120,0) -> 2 | M120: =student_habits_performance!K120 -> 3 | N120: =student_habits_performance!G120 -> No | O120: =student_habits_performance!H120 -> 72.8 | P120: =student_habits_performance!Q120 -> 2
A121: Soniya Bishwakarma | B121: #N/A | C121: 2703100948200071 | D121: =student_habits_performance!O121 -> No | E121: =student_habits_performance!I121 -> 8.3 | F121: =student_habits_performance!E121 -> 3.1 | G121: =RANDBETWEEN(0,4) -> 3 | H121: =ROUND(LOG(student_habits_performance!N121),0) -> 1 | I121: =student_habits_performance!J121 -> Fair | J121: =student_habits_performance!L121 -> High School | K121: =student_habits_performance!M121 -> Average | L121: =ROUND(student_habits_performance!F121,0) -> 2 | M121: =student_habits_performance!K121 -> 4 | N121: =student_habits_performance!G121 -> Yes | O121: =student_habits_performance!H121 -> 73.8 | P121: =student_habits_performance!Q121 -> 3
A122: Parash Sharki | B122: Male | C122: 2703100948200098 | D122: =student_habits_performance!O122 -> No | E122: =student_habits_performance!I122 -> 6.6 | F122: =student_habits_performance!E122 -> 0.4 | G122: =RANDBETWEEN(0,4) -> 2 | H122: =ROUND(LOG(student_habits_performance!N122),0) -> 1 | I122: =student_habits_performance!J122 -> Fair | J122: =student_habits_performance!L122 -> Bachelor | K122: =student_habits_performance!M122 -> Average | L122: =ROUND(student_habits_performance!F122,0) -> 1 | M122: =student_habits_performance!K122 -> 6 | N122: =student_habits_performance!G122 -> No | O122: =student_habits_performance!H122 -> 92.1 | P122: =student_habits_performance!Q122 -> 4
A123: Sulav Awasthi | B123: Male | C123: 2703100948200099 | D123: =student_habits_performance!O123 -> No | E123: =student_habits_performance!I123 -> 7.7 | F123: =student_habits_performance!E123 -> 1.7 | G123: =RANDBETWEEN(0,4) -> 0 | H123: =ROUND(LOG(student_habits_performance!N123),0) -> 0 | I123: =student_habits_performance!J123 -> Poor | J123: =student_habits_performance!L123 -> High School | K123: =student_habits_performance!M123 -> Good | L123: =ROUND(student_habits_performance!F123,0) -> 2 | M123: =student_habits_performance!K123 -> 0 | N123: =student_habits_performance!G123 -> No | O123: =student_habits_performance!H123 -> 85.2 | P123: =student_habits_performance!Q123 -> 2
A124: Karuna Khanal | B124: Female | C124: 2703100948200100 | D124: =student_habits_performance!O124 -> No | E124: =student_habits_performance!I124 -> 9.7 | F124: =student_habits_performance!E124 -> 3.9 | G124: =RANDBETWEEN(0,4) -> 0 | H124: =ROUND(LOG(student_habits_performance!N124),0) -> 0 | I124: =student_habits_performance!J124 -> Poor | J124: =student_habits_performance!L124 -> High School | K124: =student_habits_performance!M124 -> Good | L124: =ROUND(student_habits_performance!F124,0) -> 0 | M124: =student_habits_performance!K124 -> 3 | N124: =student_habits_performance!G124 -> No | O124: =student_habits_performance!H124 -> 83.6 | P124: =student_habits_performance!Q124 -> 3
A125: Ayush Raj Tiwari | B125: Male | C125: 2703100948200102 | D125: =student_habits_performance!O125 -> No | E125: =student_habits_performance!I125 -> 7.2 | F125: =student_habits_performance!E125 -> 1.3 | G125: =RANDBETWEEN(0,4) -> 3 | H125: =ROUND(LOG(student_habits_performance!N125),0) -> 1 | I125: =student_habits_performance!J125 -> Good | J125: =student_habits_performance!L125 -> Bachelor | K125: =student_habits_performance!M125 -> Average | L125: =ROUND(student_habits_performance!F125,0) -> 3 | M125: =student_habits_performance!K125 -> 1 | N125: =student_habits_performance!G125 -> No | O125: =student_habits_performance!H125 -> 80.8 | P125: =student_habits_performance!Q125 -> 3
A126: Sanaya Katharia | B126: Male | C126: 2703100948200103 | D126: =student_habits_performance!O126 -> No | E126: =student_habits_performance!I126 -> 6.6 | F126: =student_habits_performance!E126 -> 1.9 | G126: =RANDBETWEEN(0,4) -> 3 | H126: =ROUND(LOG(student_habits_performance!N126),0) -> 1 | I126: =student_habits_performance!J126 -> Fair | J126: =student_habits_performance!L126 -> Bachelor | K126: =student_habits_performance!M126 -> Average | L126: =ROUND(student_habits_performance!F126,0) -> 0 | M126: =student_habits_performance!K126 -> 2 | N126: =student_habits_performance!G126 -> No | O126: =student_habits_performance!H126 -> 81.9 | P126: =student_habits_performance!Q126 -> 2
A127: Prabesh Kumar Singh | B127: Male | C127: 1801000027700546 | D127: =student_habits_performance!O127 -> No | E127: =student_habits_performance!I127 -> 7.4 | F127: =student_habits_performance!E127 -> 3.1 | G127: =RANDBETWEEN(0,4) -> 4 | H127: =ROUND(LOG(student_habits_performance!N127),0) -> 0 | I127: =student_habits_performance!J127 -> Fair | J127: =student_habits_performance!L127 -> High School | K127: =student_habits_performance!M127 -> Average | L127: =ROUND(student_habits_performance!F127,0) -> 4 | M127: =student_habits_performance!K127 -> 0 | N127: =student_habits_performance!G127 -> No | O127: =student_habits_performance!H127 -> 95.5 | P127: =student_habits_performance!Q127 -> 2
A128: Alina Tamang | B128: Female | C128: 2700700028000451 | D128: =student_habits_performance!O128 -> No | E128: =student_habits_performance!I128 -> 6.1 | F128: =student_habits_performance!E128 -> 3.4 | G128: =RANDBETWEEN(0,4) -> 2 | H128: =ROUND(LOG(student_habits_performance!N128),0) -> 1 | I128: =student_habits_performance!J128 -> Poor | J128: =student_habits_performance!L128 -> High School | K128: =student_habits_performance!M128 -> Poor | L128: =ROUND(student_habits_performance!F128,0) -> 1 | M128: =student_habits_performance!K128 -> 1 | N128: =student_habits_performance!G128 -> Yes | O128: =student_habits_performance!H128 -> 81.6 | P128: =student_habits_performance!Q128 -> 2
A129: Kushum Magar | B129: Female | C129: 2703100948100216 | D129: =student_habits_performance!O129 -> No | E129: =student_habits_performance!I129 -> 9.4 | F129: =student_habits_performance!E129 -> 2.2 | G129: =RANDBETWEEN(0,4) -> 2 | H129: =ROUND(LOG(student_habits_performance!N129),0) -> 1 | I129: =student_habits_performance!J129 -> Good | J129: =student_habits_performance!L129 -> Bachelor | K129: =student_habits_performance!M129 -> Good | L129: =ROUND(student_habits_performance!F129,0) -> 2 | M129: =student_habits_performance!K129 -> 5 | N129: =student_habits_performance!G129 -> No | O129: =student_habits_performance!H129 -> 71.6 | P129: =student_habits_performance!Q129 -> 4
A130: Roshani Dash | B130: Female | C130: 2703100948200078 | D130: =student_habits_performance!O130 -> No | E130: =student_habits_performance!I130 -> 6.7 | F130: =student_habits_performance!E130 -> 1.8 | G130: =RANDBETWEEN(0,4) -> 1 | H130: =ROUND(LOG(student_habits_performance!N130),0) -> 0 | I130: =student_habits_performance!J130 -> Good | J130: =student_habits_performance!L130 -> High School | K130: =student_habits_performance!M130 -> Good | L130: =ROUND(student_habits_performance!F130,0) -> 1 | M130: =student_habits_performance!K130 -> 0 | N130: =student_habits_performance!G130 -> No | O130: =student_habits_performance!H130 -> 92.4 | P130: =student_habits_performance!Q130 -> 2
A131: Subarna Deuba | B131: Male | C131: 7200900508001720 | D131: =student_habits_performance!O131 -> Yes | E131: =student_habits_performance!I131 -> 6.2 | F131: =student_habits_performance!E131 -> 4.2 | G131: =RANDBETWEEN(0,4) -> 3 | H131: =ROUND(LOG(student_habits_performance!N131),0) -> 0 | I131: =student_habits_performance!J131 -> Good | J131: =student_habits_performance!L131 -> High School | K131: =student_habits_performance!M131 -> Average | L131: =ROUND(student_habits_performance!F131,0) -> 2 | M131: =student_habits_performance!K131 -> 1 | N131: =student_habits_performance!G131 -> No | O131: =student_habits_performance!H131 -> 83 | P131: =student_habits_performance!Q131 -> 1
A132: Bedana Basnet | B132: Male | C132: 2703100948200096 | D132: =student_habits_performance!O132 -> No | E132: =student_habits_performance!I132 -> 5.5 | F132: =student_habits_performance!E132 -> 4.6 | G132: =RANDBETWEEN(0,4) -> 1 | H132: =ROUND(LOG(student_habits_performance!N132),0) -> 1 | I132: =student_habits_performance!J132 -> Poor | J132: =student_habits_performance!L132 -> Bachelor | K132: =student_habits_performance!M132 -> Good | L132: =ROUND(student_habits_performance!F132,0) -> 3 | M132: =student_habits_performance!K132 -> 5 | N132: =student_habits_performance!G132 -> No | O132: =student_habits_performance!H132 -> 85.3 | P132: =student_habits_performance!Q132 -> 3
A133: Ajit Kumar Sah | B133: Male | C133: 2703100948006754 | D133: =student_habits_performance!O133 -> No | E133: =student_habits_performance!I133 -> 7.8 | F133: =student_habits_performance!E133 -> 3.7 | G133: =RANDBETWEEN(0,4) -> 4 | H133: =ROUND(LOG(student_habits_performance!N133),0) -> 1 | I133: =student_habits_performance!J133 -> Good | J133: =student_habits_performance!L133 -> High School | K133: =student_habits_performance!M133 -> Good | L133: =ROUND(student_habits_performance!F133,0) -> 0 | M133: =student_habits_performance!K133 -> 6 | N133: =student_habits_performance!G133 -> No | O133: =student_habits_performance!H133 -> 100 | P133: =student_habits_performance!Q133 -> 4
... A538: Gopal Chaudhary | B538: Male | C538: 2703100747900271 | D538: =student_habits_performance!O538 -> Yes | E538: =student_habits_performance!I538 -> 6.7 | F538: =student_habits_performance!E538 -> 3.8 | G538: =RANDBETWEEN(0,4) -> 0 | H538: =ROUND(LOG(student_habits_performance!N538),0) -> 1 | I538: =student_habits_performance!J538 -> Good | J538: =student_habits_performance!L538 -> Bachelor | K538: =student_habits_performance!M538 -> Good | L538: =ROUND(student_habits_performance!F538,0) -> 1 | M538: =student_habits_performance!K538 -> 1 | N538: =student_habits_performance!G538 -> No | O538: =student_habits_performance!H538 -> 81.3 | P538: =student_habits_performance!Q538 -> 2
A539: Sujal Khadka | B539: #N/A | C539: 2703100948200153 | D539: =student_habits_performance!O539 -> No | E539: =student_habits_performance!I539 -> 3.6 | F539: =student_habits_performance!E539 -> 0.9 | G539: =RANDBETWEEN(0,4) -> 1 | H539: =ROUND(LOG(student_habits_performance!N539),0) -> 1 | I539: =student_habits_performance!J539 -> Good | J539: =student_habits_performance!L539 -> Bachelor | K539: =student_habits_performance!M539 -> Average | L539: =ROUND(student_habits_performance!F539,0) -> 2 | M539: =student_habits_performance!K539 -> 5 | N539: =student_habits_performance!G539 -> Yes | O539: =student_habits_performance!H539 -> 80 | P539: =student_habits_performance!Q539 -> 2
A540: Anmol Tamang | B540: Male | C540: 2703100948200154 | D540: =student_habits_performance!O540 -> No | E540: =student_habits_performance!I540 -> 4.3 | F540: =student_habits_performance!E540 -> 3.2 | G540: =RANDBETWEEN(0,4) -> 1 | H540: =ROUND(LOG(student_habits_performance!N540),0) -> 1 | I540: =student_habits_performance!J540 -> Poor | J540: =student_habits_performance!L540 -> High School | K540: =student_habits_performance!M540 -> Poor | L540: =ROUND(student_habits_performance!F540,0) -> 3 | M540: =student_habits_performance!K540 -> 2 | N540: =student_habits_performance!G540 -> No | O540: =student_habits_performance!H540 -> 83.3 | P540: =student_habits_performance!Q540 -> 3
A541: Bishika Mudel | B541: Female | C541: 2703100948200156 | D541: =student_habits_performance!O541 -> Yes | E541: =student_habits_performance!I541 -> 7.2 | F541: =student_habits_performance!E541 -> 4.1 | G541: =RANDBETWEEN(0,4) -> 2 | H541: =ROUND(LOG(student_habits_performance!N541),0) -> 1 | I541: =student_habits_performance!J541 -> Good | J541: =student_habits_performance!L541 -> None | K541: =student_habits_performance!M541 -> Good | L541: =ROUND(student_habits_performance!F541,0) -> 2 | M541: =student_habits_performance!K541 -> 4 | N541: =student_habits_performance!G541 -> No | O541: =student_habits_performance!H541 -> 100 | P541: =student_habits_performance!Q541 -> 3
A542: Laukesh Baitha | B542: Male | C542: 2703100948200157 | D542: =student_habits_performance!O542 -> Yes | E542: =student_habits_performance!I542 -> 7.7 | F542: =student_habits_performance!E542 -> 3 | G542: =RANDBETWEEN(0,4) -> 4 | H542: =ROUND(LOG(student_habits_performance!N542),0) -> 1 | I542: =student_habits_performance!J542 -> Good | J542: =student_habits_performance!L542 -> Bachelor | K542: =student_habits_performance!M542 -> Average | L542: =ROUND(student_habits_performance!F542,0) -> 3 | M542: =student_habits_performance!K542 -> 3 | N542: =student_habits_performance!G542 -> No | O542: =student_habits_performance!H542 -> 83.2 | P542: =student_habits_performance!Q542 -> 3
A543: Sital Dahal | B543: Male | C543: 2703107767902574 | D543: =student_habits_performance!O543 -> No | E543: =student_habits_performance!I543 -> 5.4 | F543: =student_habits_performance!E543 -> 3.8 | G543: =RANDBETWEEN(0,4) -> 4 | H543: =ROUND(LOG(student_habits_performance!N543),0) -> 1 | I543: =student_habits_performance!J543 -> Good | J543: =student_habits_performance!L543 -> High School | K543: =student_habits_performance!M543 -> Good | L543: =ROUND(student_habits_performance!F543,0) -> 3 | M543: =student_habits_performance!K543 -> 2 | N543: =student_habits_performance!G543 -> Yes | O543: =student_habits_performance!H543 -> 84.8 | P543: =student_habits_performance!Q543 -> 3
A544: Aaditya Adhikari | B544: Male | C544: 2703100948200159 | D544: =student_habits_performance!O544 -> No | E544: =student_habits_performance!I544 -> 6.2 | F544: =student_habits_performance!E544 -> 4.9 | G544: =RANDBETWEEN(0,4) -> 3 | H544: =ROUND(LOG(student_habits_performance!N544),0) -> 1 | I544: =student_habits_performance!J544 -> Good | J544: =student_habits_performance!L544 -> Bachelor | K544: =student_habits_performance!M544 -> Poor | L544: =ROUND(student_habits_performance!F544,0) -> 1 | M544: =student_habits_performance!K544 -> 1 | N544: =student_habits_performance!G544 -> No | O544: =student_habits_performance!H544 -> 80.2 | P544: =student_habits_performance!Q544 -> 3
A545: Rajbir Kumar Haluwai | B545: Male | C545: 2703100948200166 | D545: =student_habits_performance!O545 -> No | E545: =student_habits_performance!I545 -> 6.9 | F545: =student_habits_performance!E545 -> 3.7 | G545: =RANDBETWEEN(0,4) -> 2 | H545: =ROUND(LOG(student_habits_performance!N545),0) -> 0 | I545: =student_habits_performance!J545 -> Good | J545: =student_habits_performance!L545 -> High School | K545: =student_habits_performance!M545 -> Poor | L545: =ROUND(student_habits_performance!F545,0) -> 1 | M545: =student_habits_performance!K545 -> 0 | N545: =student_habits_performance!G545 -> No | O545: =student_habits_performance!H545 -> 96 | P545: =student_habits_performance!Q545 -> 3
A546: Dinesh Thakur Lohar | B546: Male | C546: 2703100948200162 | D546: =student_habits_performance!O546 -> No | E546: =student_habits_performance!I546 -> 7.3 | F546: =student_habits_performance!E546 -> 2.8 | G546: =RANDBETWEEN(0,4) -> 1 | H546: =ROUND(LOG(student_habits_performance!N546),0) -> 1 | I546: =student_habits_performance!J546 -> Poor | J546: =student_habits_performance!L546 -> Bachelor | K546: =student_habits_performance!M546 -> Average | L546: =ROUND(student_habits_performance!F546,0) -> 2 | M546: =student_habits_performance!K546 -> 6 | N546: =student_habits_performance!G546 -> No | O546: =student_habits_performance!H546 -> 100 | P546: =student_habits_performance!Q546 -> 4
A547: Abhay Adhikari | B547: Male | C547: 1704801137901609 | D547: =student_habits_performance!O547 -> Yes | E547: =student_habits_performance!I547 -> 4.1 | F547: =student_habits_performance!E547 -> 3.8 | G547: =RANDBETWEEN(0,4) -> 1 | H547: =ROUND(LOG(student_habits_performance!N547),0) -> 1 | I547: =student_habits_performance!J547 -> Fair | J547: =student_habits_performance!L547 -> Master | K547: =student_habits_performance!M547 -> Average | L547: =ROUND(student_habits_performance!F547,0) -> 2 | M547: =student_habits_performance!K547 -> 5 | N547: =student_habits_performance!G547 -> No | O547: =student_habits_performance!H547 -> 89.5 | P547: =student_habits_performance!Q547 -> 2
A548: Sadiksha Neupane | B548: Female | C548: 2703100948200160 | D548: =student_habits_performance!O548 -> Yes | E548: =student_habits_performance!I548 -> 5.4 | F548: =student_habits_performance!E548 -> 2.7 | G548: =RANDBETWEEN(0,4) -> 1 | H548: =ROUND(LOG(student_habits_performance!N548),0) -> 0 | I548: =student_habits_performance!J548 -> Good | J548: =student_habits_performance!L548 -> Master | K548: =student_habits_performance!M548 -> Good | L548: =ROUND(student_habits_performance!F548,0) -> 1 | M548: =student_habits_performance!K548 -> 2 | N548: =student_habits_performance!G548 -> Yes | O548: =student_habits_performance!H548 -> 85.8 | P548: =student_habits_performance!Q548 -> 3
A549: Dwarika Prasad Yadav | B549: Female | C549: 2703100948200168 | D549: =student_habits_performance!O549 -> No | E549: =student_habits_performance!I549 -> 6.1 | F549: =student_habits_performance!E549 -> 2.5 | G549: =RANDBETWEEN(0,4) -> 2 | H549: =ROUND(LOG(student_habits_performance!N549),0) -> 1 | I549: =student_habits_performance!J549 -> Fair | J549: =student_habits_performance!L549 -> High School | K549: =student_habits_performance!M549 -> Good | L549: =ROUND(student_habits_performance!F549,0) -> 3 | M549: =student_habits_performance!K549 -> 6 | N549: =student_habits_performance!G549 -> No | O549: =student_habits_performance!H549 -> 85.4 | P549: =student_habits_performance!Q549 -> 4
A550: Amanat Safi | B550: Male | C550: 1704801508000065 | D550: =student_habits_performance!O550 -> No | E550: =student_habits_performance!I550 -> 7.3 | F550: =student_habits_performance!E550 -> 2.1 | G550: =RANDBETWEEN(0,4) -> 3 | H550: =ROUND(LOG(student_habits_performance!N550),0) -> 0 | I550: =student_habits_performance!J550 -> Poor | J550: =student_habits_performance!L550 -> High School | K550: =student_habits_performance!M550 -> Poor | L550: =ROUND(student_habits_performance!F550,0) -> 2 | M550: =student_habits_performance!K550 -> 6 | N550: =student_habits_performance!G550 -> No | O550: =student_habits_performance!H550 -> 61.2 | P550: =student_habits_performance!Q550 -> 3
...

Sheet scaled
A1: Student Name | B1: Gender | C1: Emis id | D1: Private_Tutoring | E1: Sleep_Hours | F1: Mobile_Usage_Hours | G1: Motivation_Level | H1: Stress_Level | I1: Study_Environment | J1: Parental_Education | K1: Family_Income_Level | L1: Peer_Influence | M1: Physical_Health_Rating | N1: Chronic_Illness | O1: Attendance_Percentage | P1: Risk_Level (TARGET)
A2: Asmita Thapa | B2: Female | C2: 2703100947805132 | D2: =student_habits_performance!O2 -> Yes | E2: =student_habits_performance!I2 -> 8 | F2: =student_habits_performance!E2 -> 1.2 | G2: 1 | H2: =ROUND(LOG(student_habits_performance!N2),0) -> 1 | I2: =student_habits_performance!J2 -> Fair | J2: =student_habits_performance!L2 -> Master | K2: =student_habits_performance!M2 -> Average | L2: =ROUND(student_habits_performance!F2,0) -> 1 | M2: =student_habits_performance!K2 -> 6 | N2: =student_habits_performance!G2 -> No | O2: =student_habits_performance!H2 -> 85 | P2: =student_habits_performance!Q2 -> 2
A3: Kamal K C | B3: Male | C3: 2703100947906290 | D3: =student_habits_performance!O3 -> No | E3: =student_habits_performance!I3 -> 4.6 | F3: =student_habits_performance!E3 -> 2.8 | G3: 2 | H3: =ROUND(LOG(student_habits_performance!N3),0) -> 1 | I3: =student_habits_performance!J3 -> Good | J3: =student_habits_performance!L3 -> High School | K3: =student_habits_performance!M3 -> Average | L3: =ROUND(student_habits_performance!F3,0) -> 2 | M3: =student_habits_performance!K3 -> 6 | N3: =student_habits_performance!G3 -> No | O3: =student_habits_performance!H3 -> 97.3 | P3: =student_habits_performance!Q3 -> 4
A4: Asmita Yesmali Magar | B4: Female | C4: 2703100947502860 | D4: =student_habits_performance!O4 -> No | E4: =student_habits_performance!I4 -> 8 | F4: =student_habits_performance!E4 -> 3.1 | G4: 3 | H4: =ROUND(LOG(student_habits_performance!N4),0) -> 0 | I4: =student_habits_performance!J4 -> Poor | J4: =student_habits_performance!L4 -> High School | K4: =student_habits_performance!M4 -> Poor | L4: =ROUND(student_habits_performance!F4,0) -> 1 | M4: =student_habits_performance!K4 -> 1 | N4: =student_habits_performance!G4 -> No | O4: =student_habits_performance!H4 -> 94.8 | P4: =student_habits_performance!Q4 -> 1
A5: Tushi Kr. Chaurasiya | B5: Male | C5: 2703100947906670 | D5: =student_habits_performance!O5 -> Yes | E5: =student_habits_performance!I5 -> 9.2 | F5: =student_habits_performance!E5 -> 3.9 | G5: 2 | H5: =ROUND(LOG(student_habits_performance!N5),0) -> 0 | I5: =student_habits_performance!J5 -> Poor | J5: =student_habits_performance!L5 -> Master | K5: =student_habits_performance!M5 -> Good | L5: =ROUND(student_habits_performance!F5,0) -> 1 | M5: =student_habits_performance!K5 -> 4 | N5: =student_habits_performance!G5 -> No | O5: =student_habits_performance!H5 -> 71 | P5: =student_habits_performance!Q5 -> 1
A6: Tulasi Kumari Khadga | B6: Female | C6: 2703100947805129 | D6: =student_habits_performance!O6 -> No | E6: =student_habits_performance!I6 -> 4.9 | F6: =student_habits_performance!E6 -> 4.4 | G6: 4 | H6: =ROUND(LOG(student_habits_performance!N6),0) -> 0 | I6: =student_habits_performance!J6 -> Fair | J6: =student_habits_performance!L6 -> Master | K6: =student_habits_performance!M6 -> Good | L6: =ROUND(student_habits_performance!F6,0) -> 1 | M6: =student_habits_performance!K6 -> 3 | N6: =student_habits_performance!G6 -> No | O6: =student_habits_performance!H6 -> 90.9 | P6: =student_habits_performance!Q6 -> 3
A7: Sushil Chandra Subedi | B7: Male | C7: 2703100947906057 | D7: =student_habits_performance!O7 -> No | E7: =student_habits_performance!I7 -> 7.4 | F7: =student_habits_performance!E7 -> 1.3 | G7: 0 | H7: =ROUND(LOG(student_habits_performance!N7),0) -> 1 | I7: =student_habits_performance!J7 -> Fair | J7: =student_habits_performance!L7 -> Master | K7: =student_habits_performance!M7 -> Average | L7: =ROUND(student_habits_performance!F7,0) -> 0 | M7: =student_habits_performance!K7 -> 1 | N7: =student_habits_performance!G7 -> No | O7: =student_habits_performance!H7 -> 82.9 | P7: =student_habits_performance!Q7 -> 4
A8: Suraj Kumar Yadav | B8: Male | C8: 2703100947805100 | D8: =student_habits_performance!O8 -> No | E8: =student_habits_performance!I8 -> 6.5 | F8: =student_habits_performance!E8 -> 1.5 | G8: 3 | H8: =ROUND(LOG(student_habits_performance!N8),0) -> 1 | I8: =student_habits_performance!J8 -> Good | J8: =student_habits_performance!L8 -> Master | K8: =student_habits_performance!M8 -> Poor | L8: =ROUND(student_habits_performance!F8,0) -> 1 | M8: =student_habits_performance!K8 -> 2 | N8: =student_habits_performance!G8 -> Yes | O8: =student_habits_performance!H8 -> 85.8 | P8: =student_habits_performance!Q8 -> 4
A9: Sima Bisunkhe | B9: Female | C9: 2703100947502857 | D9: =student_habits_performance!O9 -> No | E9: =student_habits_performance!I9 -> 4.6 | F9: =student_habits_performance!E9 -> 1 | G9: 4 | H9: =ROUND(LOG(student_habits_performance!N9),0) -> 1 | I9: =student_habits_performance!J9 -> Fair | J9: =student_habits_performance!L9 -> Bachelor | K9: =student_habits_performance!M9 -> Average | L9: =ROUND(student_habits_performance!F9,0) -> 2 | M9: =student_habits_performance!K9 -> 0 | N9: =student_habits_performance!G9 -> Yes | O9: =student_habits_performance!H9 -> 77.7 | P9: =student_habits_performance!Q9 -> 3
A10: Sudip Baniya | B10: Male | C10: 2703100948007108 | D10: =student_habits_performance!O10 -> No | E10: =student_habits_performance!I10 -> 7.1 | F10: =student_habits_performance!E10 -> 2.2 | G10: 2 | H10: =ROUND(LOG(student_habits_performance!N10),0) -> 0 | I10: =student_habits_performance!J10 -> Good | J10: =student_habits_performance!L10 -> Bachelor | K10: =student_habits_performance!M10 -> Good | L10: =ROUND(student_habits_performance!F10,0) -> 2 | M10: =student_habits_performance!K10 -> 3 | N10: =student_habits_performance!G10 -> No | O10: =student_habits_performance!H10 -> 100 | P10: =student_habits_performance!Q10 -> 3
A11: Sparsh Sah | B11: Male | C11: 2703100947906143 | D11: =student_habits_performance!O11 -> Yes | E11: =student_habits_performance!I11 -> 7.5 | F11: =student_habits_performance!E11 -> 3.1 | G11: 0 | H11: =ROUND(LOG(student_habits_performance!N11),0) -> 1 | I11: =student_habits_performance!J11 -> Good | J11: =student_habits_performance!L11 -> Bachelor | K11: =student_habits_performance!M11 -> Good | L11: =ROUND(student_habits_performance!F11,0) -> 1 | M11: =student_habits_performance!K11 -> 5 | N11: =student_habits_performance!G11 -> No | O11: =student_habits_performance!H11 -> 95.4 | P11: =student_habits_performance!Q11 -> 4
A12: Sitala Parajuli | B12: Female | C12: 2703100947502855 | D12: =student_habits_performance!O12 -> No | E12: =student_habits_performance!I12 -> 5.8 | F12: =student_habits_performance!E12 -> 3.7 | G12: 4 | H12: =ROUND(LOG(student_habits_performance!N12),0) -> 0 | I12: =student_habits_performance!J12 -> Fair | J12: =student_habits_performance!L12 -> None | K12: =student_habits_performance!M12 -> Good | L12: =ROUND(student_habits_performance!F12,0) -> 1 | M12: =student_habits_performance!K12 -> 1 | N12: =student_habits_performance!G12 -> No | O12: =student_habits_performance!H12 -> 77.6 | P12: =student_habits_performance!Q12 -> 3
A13: Siddhartha Khanal | B13: Male | C13: 2703100947906078 | D13: =student_habits_performance!O13 -> No | E13: =student_habits_performance!I13 -> 7.9 | F13: =student_habits_performance!E13 -> 2.4 | G13: 2 | H13: =ROUND(LOG(student_habits_performance!N13),0) -> 0 | I13: =student_habits_performance!J13 -> Fair | J13: =student_habits_performance!L13 -> Bachelor | K13: =student_habits_performance!M13 -> Average | L13: =ROUND(student_habits_performance!F13,0) -> 3 | M13: =student_habits_performance!K13 -> 2 | N13: =student_habits_performance!G13 -> No | O13: =student_habits_performance!H13 -> 71.7 | P13: =student_habits_performance!Q13 -> 3
... A173: KHUSHBU SAH KALWAR | B173: Female | C173: 2703100948100189 | D173: =student_habits_performance!O173 -> Yes | E173: =student_habits_performance!I173 -> 5.5 | F173: =student_habits_performance!E173 -> 2.4 | G173: 0 | H173: =ROUND(LOG(student_habits_performance!N173),0) -> 0 | I173: =student_habits_performance!J173 -> Good | J173: =student_habits_performance!L173 -> Bachelor | K173: =student_habits_performance!M173 -> Good | L173: =ROUND(student_habits_performance!F173,0) -> 0 | M173: =student_habits_performance!K173 -> 0 | N173: =student_habits_performance!G173 -> No | O173: =student_habits_performance!H173 -> 85.5 | P173: =student_habits_performance!Q173 -> 3
A174: Jems Kumar Chaudhary | B174: #N/A | C174: 2703100947603700 | D174: =student_habits_performance!O174 -> No | E174: =student_habits_performance!I174 -> 7.1 | F174: =student_habits_performance!E174 -> 0.7 | G174: 0 | H174: =ROUND(LOG(student_habits_performance!N174),0) -> 1 | I174: =student_habits_performance!J174 -> Good | J174: =student_habits_performance!L174 -> High School | K174: =student_habits_performance!M174 -> Good | L174: =ROUND(student_habits_performance!F174,0) -> 4 | M174: =student_habits_performance!K174 -> 5 | N174: =student_habits_performance!G174 -> No | O174: =student_habits_performance!H174 -> 74.3 | P174: =student_habits_performance!Q174 -> 3
A175: Ishan Lamichhane | B175: Male | C175: 2703100948007153 | D175: =student_habits_performance!O175 -> Yes | E175: =student_habits_performance!I175 -> 5.6 | F175: =student_habits_performance!E175 -> 2.1 | G175: 4 | H175: =ROUND(LOG(student_habits_performance!N175),0) -> 1 | I175: =student_habits_performance!J175 -> Fair | J175: =student_habits_performance!L175 -> Master | K175: =student_habits_performance!M175 -> Good | L175: =ROUND(student_habits_performance!F175,0) -> 2 | M175: =student_habits_performance!K175 -> 3 | N175: =student_habits_performance!G175 -> No | O175: =student_habits_performance!H175 -> 85.8 | P175: =student_habits_performance!Q175 -> 3
A176: Hima Rai | B176: Female | C176: 2703100947301644 | D176: =student_habits_performance!O176 -> No | E176: =student_habits_performance!I176 -> 7.7 | F176: =student_habits_performance!E176 -> 3.6 | G176: 3 | H176: =ROUND(LOG(student_habits_performance!N176),0) -> 0 | I176: =student_habits_performance!J176 -> Good | J176: =student_habits_performance!L176 -> High School | K176: =student_habits_performance!M176 -> Poor | L176: =ROUND(student_habits_performance!F176,0) -> 3 | M176: =student_habits_performance!K176 -> 5 | N176: =student_habits_performance!G176 -> Yes | O176: =student_habits_performance!H176 -> 80.2 | P176: =student_habits_performance!Q176 -> 3
A177: Dip Narayan Pal | B177: Male | C177: 2703100947805120 | D177: =student_habits_performance!O177 -> No | E177: =student_habits_performance!I177 -> 5 | F177: =student_habits_performance!E177 -> 3.2 | G177: 2 | H177: =ROUND(LOG(student_habits_performance!N177),0) -> 1 | I177: =student_habits_performance!J177 -> Good | J177: =student_habits_performance!L177 -> Master | K177: =student_habits_performance!M177 -> Good | L177: =ROUND(student_habits_performance!F177,0) -> 0 | M177: =student_habits_performance!K177 -> 3 | N177: =student_habits_performance!G177 -> No | O177: =student_habits_performance!H177 -> 100 | P177: =student_habits_performance!Q177 -> 3
A178: Dipesh Thapa | B178: Male | C178: 2703100948007050 | D178: =student_habits_performance!O178 -> Yes | E178: =student_habits_performance!I178 -> 7.1 | F178: =student_habits_performance!E178 -> 3.1 | G178: 2 | H178: =ROUND(LOG(student_habits_performance!N178),0) -> 1 | I178: =student_habits_performance!J178 -> Good | J178: =student_habits_performance!L178 -> High School | K178: =student_habits_performance!M178 -> Average | L178: =ROUND(student_habits_performance!F178,0) -> 0 | M178: =student_habits_performance!K178 -> 6 | N178: =student_habits_performance!G178 -> No | O178: =student_habits_performance!H178 -> 84.6 | P178: =student_habits_performance!Q178 -> 3
A179: Dilpana Shrestha | B179: Female | C179: 2703100948007096 | D179: =student_habits_performance!O179 -> Yes | E179: =student_habits_performance!I179 -> 5.5 | F179: =student_habits_performance!E179 -> 2.6 | G179: 1 | H179: =ROUND(LOG(student_habits_performance!N179),0) -> 1 | I179: =student_habits_performance!J179 -> Fair | J179: =student_habits_performance!L179 -> Master | K179: =student_habits_performance!M179 -> Average | L179: =ROUND(student_habits_performance!F179,0) -> 2 | M179: =student_habits_performance!K179 -> 0 | N179: =student_habits_performance!G179 -> No | O179: =student_habits_performance!H179 -> 71 | P179: =student_habits_performance!Q179 -> 2
A180: Chandra Prakash Regmi | B180: Male | C180: 2703100947502843 | D180: =student_habits_performance!O180 -> No | E180: =student_habits_performance!I180 -> 6.3 | F180: =student_habits_performance!E180 -> 2.5 | G180: 1 | H180: =ROUND(LOG(student_habits_performance!N180),0) -> 1 | I180: =student_habits_performance!J180 -> Poor | J180: =student_habits_performance!L180 -> None | K180: =student_habits_performance!M180 -> Good | L180: =ROUND(student_habits_performance!F180,0) -> 2 | M180: =student_habits_performance!K180 -> 5 | N180: =student_habits_performance!G180 -> Yes | O180: =student_habits_performance!H180 -> 83.7 | P180: =student_habits_performance!Q180 -> 3
A181: Bikash Majhi | B181: Male | C181: 2703100947805092 | D181: =student_habits_performance!O181 -> No | E181: =student_habits_performance!I181 -> 5.3 | F181: =student_habits_performance!E181 -> 1.7 | G181: 4 | H181: =ROUND(LOG(student_habits_performance!N181),0) -> 1 | I181: =student_habits_performance!J181 -> Good | J181: =student_habits_performance!L181 -> High School | K181: =student_habits_performance!M181 -> Average | L181: =ROUND(student_habits_performance!F181,0) -> 4 | M181: =student_habits_performance!K181 -> 2 | N181: =student_habits_performance!G181 -> No | O181: =student_habits_performance!H181 -> 90.2 | P181: =student_habits_performance!Q181 -> 2
A182: Bhawana Khatri | B182: Female | C182: 2703100947805135 | D182: =student_habits_performance!O182 -> No | E182: =student_habits_performance!I182 -> 7.5 | F182: =student_habits_performance!E182 -> 3.3 | G182: 3 | H182: =ROUND(LOG(student_habits_performance!N182),0) -> 1 | I182: =student_habits_performance!J182 -> Fair | J182: =student_habits_performance!L182 -> None | K182: =student_habits_performance!M182 -> Good | L182: =ROUND(student_habits_performance!F182,0) -> 3 | M182: =student_habits_performance!K182 -> 5 | N182: =student_habits_performance!G182 -> Yes | O182: =student_habits_performance!H182 -> 100 | P182: =student_habits_performance!Q182 -> 3
A183: Babita Rawal | B183: Female | C183: 2703100948007133 | D183: =student_habits_performance!O183 -> No | E183: =student_habits_performance!I183 -> 5.5 | F183: =student_habits_performance!E183 -> 3 | G183: 2 | H183: =ROUND(LOG(student_habits_performance!N183),0) -> 1 | I183: =student_habits_performance!J183 -> Good | J183: =student_habits_performance!L183 -> Bachelor | K183: =student_habits_performance!M183 -> Average | L183: =ROUND(student_habits_performance!F183,0) -> 2 | M183: =student_habits_performance!K183 -> 0 | N183: =student_habits_performance!G183 -> Yes | O183: =student_habits_performance!H183 -> 79.1 | P183: =student_habits_performance!Q183 -> 3
A184: Aswin Sunar | B184: Male | C184: 2703100947805108 | D184: =student_habits_performance!O184 -> No | E184: =student_habits_performance!I184 -> 7.2 | F184: =student_habits_performance!E184 -> 3.1 | G184: 2 | H184: =ROUND(LOG(student_habits_performance!N184),0) -> 1 | I184: =student_habits_performance!J184 -> Good | J184: =student_habits_performance!L184 -> Master | K184: =student_habits_performance!M184 -> Poor | L184: =ROUND(student_habits_performance!F184,0) -> 1 | M184: =student_habits_performance!K184 -> 1 | N184: =student_habits_performance!G184 -> No | O184: =student_habits_performance!H184 -> 69.2 | P184: =student_habits_performance!Q184 -> 3
A185: Archana Rai | B185: Female | C185: 2703100947502835 | D185: =student_habits_performance!O185 -> Yes | E185: =student_habits_performance!I185 -> 6.1 | F185: =student_habits_performance!E185 -> 1.9 | G185: 0 | H185: =ROUND(LOG(student_habits_performance!N185),0) -> 1 | I185: =student_habits_performance!J185 -> Fair | J185: =student_habits_performance!L185 -> High School | K185: =student_habits_performance!M185 -> Average | L185: =ROUND(student_habits_performance!F185,0) -> 3 | M185: =student_habits_performance!K185 -> 1 | N185: =student_habits_performance!G185 -> No | O185: =student_habits_performance!H185 -> 93.2 | P185: =student_habits_performance!Q185 -> 3
A186: Anisha Basnet | B186: Female | C186: 2703100947905851 | D186: =student_habits_performance!O186 -> No | E186: =student_habits_performance!I186 -> 6.4 | F186: =student_habits_performance!E186 -> 0 | G186: 0 | H186: =ROUND(LOG(student_habits_performance!N186),0) -> 1 | I186: =student_habits_performance!J186 -> Fair | J186: =student_habits_performance!L186 -> Master | K186: =student_habits_performance!M186 -> Poor | L186: =ROUND(student_habits_performance!F186,0) -> 1 | M186: =student_habits_performance!K186 -> 5 | N186: =student_habits_performance!G186 -> No | O186: =student_habits_performance!H186 -> 71.2 | P186: =student_habits_performance!Q186 -> 4
... A299: Aashirbad Patel | B299: Male | C299: 2703100947805134 | D299: =student_habits_performance!O299 -> No | E299: =student_habits_performance!I299 -> 3.5 | F299: =student_habits_performance!E299 -> 2.8 | G299: 1 | H299: =ROUND(LOG(student_habits_performance!N299),0) -> 0 | I299: =student_habits_performance!J299 -> Good | J299: =student_habits_performance!L299 -> Master | K299: =student_habits_performance!M299 -> Average | L299: =ROUND(student_habits_performance!F299,0) -> 1 | M299: =student_habits_performance!K299 -> 2 | N299: =student_habits_performance!G299 -> No | O299: =student_habits_performance!H299 -> 82.4 | P299: =student_habits_performance!Q299 -> 2
A300: Sumit Roka Magar | B300: #N/A | C300: 2703100947906103 | D300: =student_habits_performance!O300 -> Yes | E300: =student_habits_performance!I300 -> 6.2 | F300: =student_habits_performance!E300 -> 3.1 | G300: 2 | H300: =ROUND(LOG(student_habits_performance!N300),0) -> 1 | I300: =student_habits_performance!J300 -> Poor | J300: =student_habits_performance!L300 -> High School | K300: =student_habits_performance!M300 -> Average | L300: =ROUND(student_habits_performance!F300,0) -> 2 | M300: =student_habits_performance!K300 -> 3 | N300: =student_habits_performance!G300 -> No | O300: =student_habits_performance!H300 -> 88.1 | P300: =student_habits_performance!Q300 -> 4
A301: Smile Darnal | B301: Male | C301: 2703100948100399 | D301: =student_habits_performance!O301 -> No | E301: =student_habits_performance!I301 -> 7.7 | F301: =student_habits_performance!E301 -> 3.1 | G301: 3 | H301: =ROUND(LOG(student_habits_performance!N301),0) -> 1 | I301: =student_habits_performance!J301 -> Fair | J301: =student_habits_performance!L301 -> Bachelor | K301: =student_habits_performance!M301 -> Average | L301: =ROUND(student_habits_performance!F301,0) -> 1 | M301: =student_habits_performance!K301 -> 3 | N301: =student_habits_performance!G301 -> No | O301: =student_habits_performance!H301 -> 100 | P301: =student_habits_performance!Q301 -> 4
A302: Sangnima Sherpa | B302: Male | C302: 2703100948100394 | D302: =student_habits_performance!O302 -> Yes | E302: =student_habits_performance!I302 -> 5.7 | F302: =student_habits_performance!E302 -> 2.6 | G302: 2 | H302: =ROUND(LOG(student_habits_performance!N302),0) -> 1 | I302: =student_habits_performance!J302 -> Poor | J302: =student_habits_performance!L302 -> High School | K302: =student_habits_performance!M302 -> Good | L302: =ROUND(student_habits_performance!F302,0) -> 4 | M302: =student_habits_performance!K302 -> 6 | N302: =student_habits_performance!G302 -> No | O302: =student_habits_performance!H302 -> 71 | P302: =student_habits_performance!Q302 -> 2
A303: Sandesh Shahi | B303: Male | C303: 2703100947704273 | D303: =student_habits_performance!O303 -> No | E303: =student_habits_performance!I303 -> 6.6 | F303: =student_habits_performance!E303 -> 3.4 | G303: 0 | H303: =ROUND(LOG(student_habits_performance!N303),0) -> 1 | I303: =student_habits_performance!J303 -> Good | J303: =student_habits_performance!L303 -> High School | K303: =student_habits_performance!M303 -> Average | L303: =ROUND(student_habits_performance!F303,0) -> 4 | M303: =student_habits_performance!K303 -> 3 | N303: =student_habits_performance!G303 -> Yes | O303: =student_habits_performance!H303 -> 97 | P303: =student_habits_performance!Q303 -> 2
A304: Sachin Chaudhary | B304: #N/A | C304: 2703100948200376 | D304: =student_habits_performance!O304 -> No | E304: =student_habits_performance!I304 -> 5.6 | F304: =student_habits_performance!E304 -> 3.1 | G304: 4 | H304: =ROUND(LOG(student_habits_performance!N304),0) -> 1 | I304: =student_habits_performance!J304 -> Fair | J304: =student_habits_performance!L304 -> High School | K304: =student_habits_performance!M304 -> Poor | L304: =ROUND(student_habits_performance!F304,0) -> 2 | M304: =student_habits_performance!K304 -> 5 | N304: =student_habits_performance!G304 -> No | O304: =student_habits_performance!H304 -> 86.8 | P304: =student_habits_performance!Q304 -> 3
